<?xml version="1.0" ?>
<!-- =================================================================================== -->
<!-- |    This document was autogenerated by xacro from follower.urdf.xacro            | -->
<!-- |    EDITING THIS FILE BY HAND IS NOT RECOMMENDED                                 | -->
<!-- =================================================================================== -->
<robot name="follower">
  <link name="world"/>
  <joint name="world_fixed" type="fixed">
    <parent link="world"/>
    <child link="base_link"/>
    <origin rpy="0 0 0" xyz="0.0 0.0 0.0"/>
  </joint>
  <!-- 2-DOF에는 end_effector 고정조인트가 필요 없으면 제거 가능.
       샘플 구조를 유지하기 위해 남겨두되, link2에 고정한다고 가정 -->
  <!-- <joint name="$(arg prefix)end_effector_joint" type="fixed">
    <parent link="$(arg prefix)link2"/>
    <child link="$(arg prefix)end_effector_link"/>
    <origin xyz="0.10 0.0 0.0" rpy="0 0 0"/>
  </joint>

  <link name="$(arg prefix)end_effector_link">
    <visual>
      <origin xyz="0 0 0" rpy="0 0 0"/>
      <geometry>
        <box size="0.01 0.01 0.01" />
      </geometry>
      <material name="red">
        <color rgba="1.0 0.0 0.0 1"/>
      </material>
    </visual>
  </link> -->
  <material name="black">
    <color rgba="0.0 0.0 0.0 1.0"/>
  </material>
  <material name="dark_gray">
    <color rgba="0.2 0.2 0.2 1.0"/>
  </material>
  <material name="white">
    <color rgba="1.0 1.0 1.0 1.0"/>
  </material>
  <link name="base_link">
    <inertial>
      <origin rpy="0 0 0" xyz="1.197034860872733e-05 2.2046610134709234e-05 0.13090240145620716"/>
      <mass value="10.533144791374717"/>
      <inertia ixx="0.529558" ixy="8e-06" ixz="-6.1e-05" iyy="0.526156" iyz="-0.000118" izz="0.107055"/>
    </inertial>
    <visual>
      <origin rpy="0 0 0" xyz="0 0 0"/>
      <geometry>
        <mesh filename="file:///home/shin/avatar_ws/install/avatar_description/share/avatar_description/meshes/follower/base_link.stl" scale="0.01 0.01 0.01"/>
      </geometry>
      <material name="dark_gray"/>
    </visual>
    <collision>
      <origin rpy="0 0 0" xyz="0 0 0"/>
      <geometry>
        <mesh filename="file:///home/shin/avatar_ws/install/avatar_description/share/avatar_description/meshes/follower/base_link.stl" scale="0.01 0.01 0.01"/>
      </geometry>
    </collision>
  </link>
  <link name="left_link1_1">
    <inertial>
      <origin rpy="0 0 0" xyz="3.2842893861874216e-09 0.0339438363239903 0.004338426588372579"/>
      <mass value="0.05267109101640789"/>
      <inertia ixx="3.3e-05" ixy="0.0" ixz="0.0" iyy="3.2e-05" iyz="-4e-06" izz="4.1e-05"/>
    </inertial>
    <visual>
      <origin rpy="0 0 0" xyz="0.00025 -0.1025 -0.6155"/>
      <geometry>
        <mesh filename="file:///home/shin/avatar_ws/install/avatar_description/share/avatar_description/meshes/follower/left_link1_1.stl" scale="0.01 0.01 0.01"/>
      </geometry>
      <material name="dark_gray"/>
    </visual>
    <collision>
      <origin rpy="0 0 0" xyz="0.00025 -0.1025 -0.6155"/>
      <geometry>
        <mesh filename="file:///home/shin/avatar_ws/install/avatar_description/share/avatar_description/meshes/follower/left_link1_1.stl" scale="0.01 0.01 0.01"/>
      </geometry>
    </collision>
  </link>
  <link name="right_link1_1">
    <inertial>
      <origin rpy="0 0 0" xyz="-3.2842893531192553e-09 -0.03394383632399016 0.004338426588372579"/>
      <mass value="0.05267109101640788"/>
      <inertia ixx="3.3e-05" ixy="0.0" ixz="-0.0" iyy="3.2e-05" iyz="4e-06" izz="4.1e-05"/>
    </inertial>
    <visual>
      <origin rpy="0 0 0" xyz="-0.00025 0.1025 -0.6155"/>
      <geometry>
        <mesh filename="file:///home/shin/avatar_ws/install/avatar_description/share/avatar_description/meshes/follower/right_link1_1.stl" scale="0.01 0.01 0.01"/>
      </geometry>
      <material name="dark_gray"/>
    </visual>
    <collision>
      <origin rpy="0 0 0" xyz="-0.00025 0.1025 -0.6155"/>
      <geometry>
        <mesh filename="file:///home/shin/avatar_ws/install/avatar_description/share/avatar_description/meshes/follower/right_link1_1.stl" scale="0.01 0.01 0.01"/>
      </geometry>
    </collision>
  </link>
  <link name="neck_link1_1">
    <inertial>
      <origin rpy="0 0 0" xyz="-0.00030973850909889926 -0.014644333953918068 0.03569874341148194"/>
      <mass value="0.17638315081350112"/>
      <inertia ixx="0.000175" ixy="-0.0" ixz="1e-06" iyy="0.000123" iyz="-4e-06" izz="0.00019"/>
    </inertial>
    <visual>
      <origin rpy="0 0 0" xyz="-0.00025 -0.0194 -0.6478"/>
      <geometry>
        <mesh filename="file:///home/shin/avatar_ws/install/avatar_description/share/avatar_description/meshes/follower/neck_link1_1.stl" scale="0.01 0.01 0.01"/>
      </geometry>
      <material name="dark_gray"/>
    </visual>
    <collision>
      <origin rpy="0 0 0" xyz="-0.00025 -0.0194 -0.6478"/>
      <geometry>
        <mesh filename="file:///home/shin/avatar_ws/install/avatar_description/share/avatar_description/meshes/follower/neck_link1_1.stl" scale="0.01 0.01 0.01"/>
      </geometry>
    </collision>
  </link>
  <link name="neck_link2_1">
    <inertial>
      <origin rpy="0 0 0" xyz="0.013634139305983414 0.0007303949446386359 0.035430103721878825"/>
      <mass value="0.571131718488463"/>
      <inertia ixx="0.000802" ixy="0.0" ixz="-2e-06" iyy="0.000388" iyz="0.0" izz="0.000903"/>
    </inertial>
    <visual>
      <origin rpy="0 0 0" xyz="-0.00025 -0.0004 -0.70755"/>
      <geometry>
        <mesh filename="file:///home/shin/avatar_ws/install/avatar_description/share/avatar_description/meshes/follower/neck_link2_1.stl" scale="0.01 0.01 0.01"/>
      </geometry>
      <material name="white"/>
    </visual>
    <collision>
      <origin rpy="0 0 0" xyz="-0.00025 -0.0004 -0.70755"/>
      <geometry>
        <mesh filename="file:///home/shin/avatar_ws/install/avatar_description/share/avatar_description/meshes/follower/neck_link2_1.stl" scale="0.01 0.01 0.01"/>
      </geometry>
    </collision>
  </link>
  <link name="left_link2_1">
    <inertial>
      <origin rpy="0 0 0" xyz="-0.02738813477340827 0.0003646764139110803 -0.06351763830886736"/>
      <mass value="0.4119071163979643"/>
      <inertia ixx="0.001331" ixy="-0.0" ixz="-9.7e-05" iyy="0.001381" iyz="-8e-06" izz="0.000168"/>
    </inertial>
    <visual>
      <origin rpy="0 0 0" xyz="-0.02425 -0.1525 -0.6155"/>
      <geometry>
        <mesh filename="file:///home/shin/avatar_ws/install/avatar_description/share/avatar_description/meshes/follower/left_link2_1.stl" scale="0.01 0.01 0.01"/>
      </geometry>
      <material name="dark_gray"/>
    </visual>
    <collision>
      <origin rpy="0 0 0" xyz="-0.02425 -0.1525 -0.6155"/>
      <geometry>
        <mesh filename="file:///home/shin/avatar_ws/install/avatar_description/share/avatar_description/meshes/follower/left_link2_1.stl" scale="0.01 0.01 0.01"/>
      </geometry>
    </collision>
  </link>
  <link name="left_link3_1">
    <inertial>
      <origin rpy="0 0 0" xyz="-1.2092751239928777e-08 1.2973242757841064e-09 -0.026072371405695793"/>
      <mass value="0.050293199431630714"/>
      <inertia ixx="3.7e-05" ixy="0.0" ixz="0.0" iyy="2.3e-05" iyz="-0.0" izz="3.4e-05"/>
    </inertial>
    <visual>
      <origin rpy="0 0 0" xyz="0.00025 -0.1525 -0.45775"/>
      <geometry>
        <mesh filename="file:///home/shin/avatar_ws/install/avatar_description/share/avatar_description/meshes/follower/left_link3_1.stl" scale="0.01 0.01 0.01"/>
      </geometry>
      <material name="dark_gray"/>
    </visual>
    <collision>
      <origin rpy="0 0 0" xyz="0.00025 -0.1525 -0.45775"/>
      <geometry>
        <mesh filename="file:///home/shin/avatar_ws/install/avatar_description/share/avatar_description/meshes/follower/left_link3_1.stl" scale="0.01 0.01 0.01"/>
      </geometry>
    </collision>
  </link>
  <link name="left_link4_1">
    <inertial>
      <origin rpy="0 0 0" xyz="-0.004070974019487877 -0.018903692607189798 -0.06334059246636403"/>
      <mass value="0.31397838075435874"/>
      <inertia ixx="0.000908" ixy="-0.0" ixz="-7.3e-05" iyy="0.000935" iyz="-2e-06" izz="0.000116"/>
    </inertial>
    <visual>
      <origin rpy="0 0 0" xyz="0.00025 -0.1715 -0.42625"/>
      <geometry>
        <mesh filename="file:///home/shin/avatar_ws/install/avatar_description/share/avatar_description/meshes/follower/left_link4_1.stl" scale="0.01 0.01 0.01"/>
      </geometry>
      <material name="dark_gray"/>
    </visual>
    <collision>
      <origin rpy="0 0 0" xyz="0.00025 -0.1715 -0.42625"/>
      <geometry>
        <mesh filename="file:///home/shin/avatar_ws/install/avatar_description/share/avatar_description/meshes/follower/left_link4_1.stl" scale="0.01 0.01 0.01"/>
      </geometry>
    </collision>
  </link>
  <link name="left_link5_1">
    <inertial>
      <origin rpy="0 0 0" xyz="2.8685271546600392e-08 1.2810758009962342e-09 -0.017987620476692334"/>
      <mass value="0.02546967835110524"/>
      <inertia ixx="1.2e-05" ixy="0.0" ixz="-0.0" iyy="7e-06" iyz="-0.0" izz="1.1e-05"/>
    </inertial>
    <visual>
      <origin rpy="0 0 0" xyz="0.00025 -0.1525 -0.28615"/>
      <geometry>
        <mesh filename="file:///home/shin/avatar_ws/install/avatar_description/share/avatar_description/meshes/follower/left_link5_1.stl" scale="0.01 0.01 0.01"/>
      </geometry>
      <material name="dark_gray"/>
    </visual>
    <collision>
      <origin rpy="0 0 0" xyz="0.00025 -0.1525 -0.28615"/>
      <geometry>
        <mesh filename="file:///home/shin/avatar_ws/install/avatar_description/share/avatar_description/meshes/follower/left_link5_1.stl" scale="0.01 0.01 0.01"/>
      </geometry>
    </collision>
  </link>
  <link name="left_link6_1">
    <inertial>
      <origin rpy="0 0 0" xyz="0.00017312528224349425 -0.02085009010277386 -0.030500463697734653"/>
      <mass value="0.19487379537642757"/>
      <inertia ixx="0.000139" ixy="-0.0" ixz="1e-06" iyy="0.00013" iyz="-1.4e-05" izz="5.7e-05"/>
    </inertial>
    <visual>
      <origin rpy="0 0 0" xyz="0.00025 -0.1715 -0.25465"/>
      <geometry>
        <mesh filename="file:///home/shin/avatar_ws/install/avatar_description/share/avatar_description/meshes/follower/left_link6_1.stl" scale="0.01 0.01 0.01"/>
      </geometry>
      <material name="dark_gray"/>
    </visual>
    <collision>
      <origin rpy="0 0 0" xyz="0.00025 -0.1715 -0.25465"/>
      <geometry>
        <mesh filename="file:///home/shin/avatar_ws/install/avatar_description/share/avatar_description/meshes/follower/left_link6_1.stl" scale="0.01 0.01 0.01"/>
      </geometry>
    </collision>
  </link>
  <link name="left_link_gripper_1">
    <inertial>
      <origin rpy="0 0 0" xyz="-0.022004443717257835 0.018430761900261827 -0.031128994083327033"/>
      <mass value="0.022581332723262154"/>
      <inertia ixx="1.9e-05" ixy="-0.0" ixz="0.0" iyy="2.8e-05" iyz="1e-06" izz="1.2e-05"/>
    </inertial>
    <visual>
      <origin rpy="0 0 0" xyz="-0.01875 -0.1629 -0.20515"/>
      <geometry>
        <mesh filename="file:///home/shin/avatar_ws/install/avatar_description/share/avatar_description/meshes/follower/left_link_gripper_1.stl" scale="0.01 0.01 0.01"/>
      </geometry>
      <material name="dark_gray"/>
    </visual>
    <collision name="left_link_gripper_1_collision">
      <origin rpy="0 0 0" xyz="-0.01875 -0.1629 -0.20515"/>
      <geometry>
        <mesh filename="file:///home/shin/avatar_ws/install/avatar_description/share/avatar_description/meshes/follower/left_link_gripper_1.stl" scale="0.01 0.01 0.01"/>
      </geometry>
    </collision>
  </link>
  <link name="right_link2_1">
    <inertial>
      <origin rpy="0 0 0" xyz="-0.02727565185538715 -0.00036463615065041033 -0.06351762777052061"/>
      <mass value="0.4119072353618623"/>
      <inertia ixx="0.001331" ixy="1e-06" ixz="-9.8e-05" iyy="0.001382" iyz="8e-06" izz="0.000168"/>
    </inertial>
    <visual>
      <origin rpy="0 0 0" xyz="-0.02475 0.1525 -0.6155"/>
      <geometry>
        <mesh filename="file:///home/shin/avatar_ws/install/avatar_description/share/avatar_description/meshes/follower/right_link2_1.stl" scale="0.01 0.01 0.01"/>
      </geometry>
      <material name="dark_gray"/>
    </visual>
    <collision>
      <origin rpy="0 0 0" xyz="-0.02475 0.1525 -0.6155"/>
      <geometry>
        <mesh filename="file:///home/shin/avatar_ws/install/avatar_description/share/avatar_description/meshes/follower/right_link2_1.stl" scale="0.01 0.01 0.01"/>
      </geometry>
    </collision>
  </link>
  <link name="right_link3_1">
    <inertial>
      <origin rpy="0 0 0" xyz="-1.209275128617e-08 -1.2656755643547513e-09 -0.026072371405695682"/>
      <mass value="0.050293199431630714"/>
      <inertia ixx="3.7e-05" ixy="0.0" ixz="0.0" iyy="2.3e-05" iyz="-0.0" izz="3.4e-05"/>
    </inertial>
    <visual>
      <origin rpy="0 0 0" xyz="-0.00025 0.1525 -0.45775"/>
      <geometry>
        <mesh filename="file:///home/shin/avatar_ws/install/avatar_description/share/avatar_description/meshes/follower/right_link3_1.stl" scale="0.01 0.01 0.01"/>
      </geometry>
      <material name="dark_gray"/>
    </visual>
    <collision>
      <origin rpy="0 0 0" xyz="-0.00025 0.1525 -0.45775"/>
      <geometry>
        <mesh filename="file:///home/shin/avatar_ws/install/avatar_description/share/avatar_description/meshes/follower/right_link3_1.stl" scale="0.01 0.01 0.01"/>
      </geometry>
    </collision>
  </link>
  <link name="right_link4_1">
    <inertial>
      <origin rpy="0 0 0" xyz="-0.0040709740464307306 0.018876725019776414 -0.06334059246636403"/>
      <mass value="0.31397838075435874"/>
      <inertia ixx="0.000908" ixy="0.0" ixz="-7.3e-05" iyy="0.000935" iyz="2e-06" izz="0.000116"/>
    </inertial>
    <visual>
      <origin rpy="0 0 0" xyz="-0.00025 0.1715 -0.42625"/>
      <geometry>
        <mesh filename="file:///home/shin/avatar_ws/install/avatar_description/share/avatar_description/meshes/follower/right_link4_1.stl" scale="0.01 0.01 0.01"/>
      </geometry>
      <material name="dark_gray"/>
    </visual>
    <collision>
      <origin rpy="0 0 0" xyz="-0.00025 0.1715 -0.42625"/>
      <geometry>
        <mesh filename="file:///home/shin/avatar_ws/install/avatar_description/share/avatar_description/meshes/follower/right_link4_1.stl" scale="0.01 0.01 0.01"/>
      </geometry>
    </collision>
  </link>
  <link name="right_link5_1">
    <inertial>
      <origin rpy="0 0 0" xyz="2.8685270933538273e-08 -1.2819240391426234e-09 -0.01798762047669228"/>
      <mass value="0.02546967835110524"/>
      <inertia ixx="1.2e-05" ixy="0.0" ixz="-0.0" iyy="7e-06" iyz="-0.0" izz="1.1e-05"/>
    </inertial>
    <visual>
      <origin rpy="0 0 0" xyz="-0.00025 0.1525 -0.28615"/>
      <geometry>
        <mesh filename="file:///home/shin/avatar_ws/install/avatar_description/share/avatar_description/meshes/follower/right_link5_1.stl" scale="0.01 0.01 0.01"/>
      </geometry>
      <material name="dark_gray"/>
    </visual>
    <collision>
      <origin rpy="0 0 0" xyz="-0.00025 0.1525 -0.28615"/>
      <geometry>
        <mesh filename="file:///home/shin/avatar_ws/install/avatar_description/share/avatar_description/meshes/follower/right_link5_1.stl" scale="0.01 0.01 0.01"/>
      </geometry>
    </collision>
  </link>
  <link name="right_link6_1">
    <inertial>
      <origin rpy="0 0 0" xyz="0.00017312522335896592 0.020213672315239545 -0.03049306440428448"/>
      <mass value="0.19487379537642624"/>
      <inertia ixx="0.000139" ixy="0.0" ixz="1e-06" iyy="0.00013" iyz="1.1e-05" izz="5.6e-05"/>
    </inertial>
    <visual>
      <origin rpy="0 0 0" xyz="-0.00025 0.1715 -0.25465"/>
      <geometry>
        <mesh filename="file:///home/shin/avatar_ws/install/avatar_description/share/avatar_description/meshes/follower/right_link6_1.stl" scale="0.01 0.01 0.01"/>
      </geometry>
      <material name="dark_gray"/>
    </visual>
    <collision>
      <origin rpy="0 0 0" xyz="-0.00025 0.1715 -0.25465"/>
      <geometry>
        <mesh filename="file:///home/shin/avatar_ws/install/avatar_description/share/avatar_description/meshes/follower/right_link6_1.stl" scale="0.01 0.01 0.01"/>
      </geometry>
    </collision>
  </link>
  <link name="right_link_gripper_1">
    <inertial>
      <origin rpy="0 0 0" xyz="-0.01899555242215849 -0.01843075902288205 -0.031128985762427674"/>
      <mass value="0.022581338744717485"/>
      <inertia ixx="1.9e-05" ixy="-0.0" ixz="-0.0" iyy="2.8e-05" iyz="-1e-06" izz="1.2e-05"/>
    </inertial>
    <visual>
      <origin rpy="0 0 0" xyz="-0.01925 0.1645 -0.20515"/>
      <geometry>
        <mesh filename="file:///home/shin/avatar_ws/install/avatar_description/share/avatar_description/meshes/follower/right_link_gripper_1.stl" scale="0.01 0.01 0.01"/>
      </geometry>
      <material name="dark_gray"/>
    </visual>
    <collision name="right_link_gripper_1_collision">
      <origin rpy="0 0 0" xyz="-0.01925 0.1645 -0.20515"/>
      <geometry>
        <mesh filename="file:///home/shin/avatar_ws/install/avatar_description/share/avatar_description/meshes/follower/right_link_gripper_1.stl" scale="0.01 0.01 0.01"/>
      </geometry>
    </collision>
  </link>
  <joint name="right_joint1" type="continuous">
    <origin rpy="0 0 0" xyz="0.00025 -0.1025 0.6155"/>
    <parent link="base_link"/>
    <child link="right_link1_1"/>
    <axis xyz="-0.0 -1.0 0.0"/>
    <limit effort="30" lower="-6.283185307179586" upper="6.283185307179586" velocity="4.8"/>
    <dynamics damping="0.1"/>
  </joint>
  <joint name="right_joint2" type="continuous">
    <origin rpy="0 0 0" xyz="0.0245 -0.05 0.0"/>
    <parent link="right_link1_1"/>
    <child link="right_link2_1"/>
    <axis xyz="-1.0 -0.0 0.0"/>
    <limit effort="30" lower="-6.283185307179586" upper="6.283185307179586" velocity="4.8"/>
    <dynamics damping="0.1"/>
  </joint>
  <joint name="right_joint3" type="continuous">
    <origin rpy="0 0 0" xyz="-0.0245 0.0 -0.15775"/>
    <parent link="right_link2_1"/>
    <child link="right_link3_1"/>
    <axis xyz="0.0 -0.0 -1.0"/>
    <limit effort="30" lower="-6.283185307179586" upper="6.283185307179586" velocity="4.8"/>
    <dynamics damping="0.1"/>
  </joint>
  <joint name="right_joint4" type="continuous">
    <origin rpy="0 0 0" xyz="0.0 -0.019 -0.0315"/>
    <parent link="right_link3_1"/>
    <child link="right_link4_1"/>
    <axis xyz="0.0 1.0 -0.0"/>
    <limit effort="30" lower="-6.283185307179586" upper="6.283185307179586" velocity="4.8"/>
    <dynamics damping="0.1"/>
  </joint>
  <joint name="right_joint5" type="continuous">
    <origin rpy="0 0 0" xyz="0.0 0.019 -0.1401"/>
    <parent link="right_link4_1"/>
    <child link="right_link5_1"/>
    <axis xyz="0.0 0.0 -1.0"/>
    <limit effort="30" lower="-6.283185307179586" upper="6.283185307179586" velocity="4.8"/>
    <dynamics damping="0.1"/>
  </joint>
  <joint name="right_joint6" type="continuous">
    <origin rpy="0 0 0" xyz="0.0 -0.019 -0.0315"/>
    <parent link="right_link5_1"/>
    <child link="right_link6_1"/>
    <axis xyz="0.0 1.0 0.0"/>
    <limit effort="30" lower="-6.283185307179586" upper="6.283185307179586" velocity="4.8"/>
    <dynamics damping="0.1"/>
  </joint>
  <joint name="right_joint_gripper" type="continuous">
    <origin rpy="0 0 0" xyz="0.019 0.007 -0.0495"/>
    <parent link="right_link6_1"/>
    <child link="right_link_gripper_1"/>
    <axis xyz="1.0 -0.0 -0.0"/>
    <limit effort="30" lower="-6.283185307179586" upper="6.283185307179586" velocity="4.8"/>
    <dynamics damping="0.1"/>
  </joint>
  <joint name="left_joint1" type="continuous">
    <origin rpy="0 0 0" xyz="-0.00025 0.1025 0.6155"/>
    <parent link="base_link"/>
    <child link="left_link1_1"/>
    <axis xyz="0.0 1.0 0.0"/>
    <limit effort="30" lower="-6.283185307179586" upper="6.283185307179586" velocity="4.8"/>
    <dynamics damping="0.1"/>
  </joint>
  <joint name="left_joint2" type="continuous">
    <origin rpy="0 0 0" xyz="0.0245 0.05 0.0"/>
    <parent link="left_link1_1"/>
    <child link="left_link2_1"/>
    <axis xyz="-1.0 -0.0 -0.0"/>
    <limit effort="30" lower="-6.283185307179586" upper="6.283185307179586" velocity="4.8"/>
    <dynamics damping="0.1"/>
  </joint>
  <joint name="left_joint3" type="continuous">
    <origin rpy="0 0 0" xyz="-0.0245 0.0 -0.15775"/>
    <parent link="left_link2_1"/>
    <child link="left_link3_1"/>
    <axis xyz="0.0 -0.0 -1.0"/>
    <limit effort="30" lower="-6.283185307179586" upper="6.283185307179586" velocity="4.8"/>
    <dynamics damping="0.1"/>
  </joint>
  <joint name="left_joint4" type="continuous">
    <origin rpy="0 0 0" xyz="0.0 0.019 -0.0315"/>
    <parent link="left_link3_1"/>
    <child link="left_link4_1"/>
    <axis xyz="-0.0 -1.0 0.0"/>
    <limit effort="30" lower="-6.283185307179586" upper="6.283185307179586" velocity="4.8"/>
    <dynamics damping="0.1"/>
  </joint>
  <joint name="left_joint5" type="continuous">
    <origin rpy="0 0 0" xyz="0.0 -0.019 -0.1401"/>
    <parent link="left_link4_1"/>
    <child link="left_link5_1"/>
    <axis xyz="0.0 0.0 -1.0"/>
    <limit effort="30" lower="-6.283185307179586" upper="6.283185307179586" velocity="4.8"/>
    <dynamics damping="0.1"/>
  </joint>
  <joint name="left_joint6" type="continuous">
    <origin rpy="0 0 0" xyz="0.0 0.019 -0.0315"/>
    <parent link="left_link5_1"/>
    <child link="left_link6_1"/>
    <axis xyz="-0.0 -1.0 -0.0"/>
    <limit effort="30" lower="-6.283185307179586" upper="6.283185307179586" velocity="4.8"/>
    <dynamics damping="0.1"/>
  </joint>
  <joint name="left_joint_gripper" type="continuous">
    <origin rpy="0 0 0" xyz="0.019 -0.0086 -0.0495"/>
    <parent link="left_link6_1"/>
    <child link="left_link_gripper_1"/>
    <axis xyz="1.0 -0.0 -0.0"/>
    <limit effort="30" lower="-6.283185307179586" upper="6.283185307179586" velocity="4.8"/>
    <dynamics damping="0.1"/>
  </joint>
  <joint name="neck_joint1" type="continuous">
    <origin rpy="0 0 0" xyz="0.00025 0.0194 0.6478"/>
    <parent link="base_link"/>
    <child link="neck_link1_1"/>
    <axis xyz="0.0 1.0 -0.0"/>
    <limit effort="30" lower="-6.283185307179586" upper="6.283185307179586" velocity="4.8"/>
    <dynamics damping="0.1"/>
  </joint>
  <joint name="neck_joint2" type="continuous">
    <origin rpy="0 0 0" xyz="0.0 -0.019 0.05975"/>
    <parent link="neck_link1_1"/>
    <child link="neck_link2_1"/>
    <axis xyz="0.0 0.0 1.0"/>
    <limit effort="30" lower="-6.283185307179586" upper="6.283185307179586" velocity="4.8"/>
    <dynamics damping="0.1"/>
  </joint>
  <gazebo reference="left_link_gripper_1">
    <sensor name="left_gripper_bumper" type="contact">
      <always_on>true</always_on>
      <update_rate>50.0</update_rate>
      <contact>
        <collision>left_link_gripper_1_collision_collision</collision>
      </contact>
      <plugin filename="libignition-gazebo-contact-system.so" name="ignition::gazebo::systems::Contact">
        </plugin>
    </sensor>
  </gazebo>
  <gazebo reference="right_link_gripper_1">
    <sensor name="right_gripper_bumper" type="contact">
      <always_on>true</always_on>
      <update_rate>50.0</update_rate>
      <contact>
        <collision>right_link_gripper_1_collision_collision</collision>
      </contact>
      <plugin filename="libignition-gazebo-contact-system.so" name="ignition::gazebo::systems::Contact">
        </plugin>
    </sensor>
  </gazebo>
  <gazebo reference="link0">
    <kp>1000000.0</kp>
    <kd>100.0</kd>
    <mu1>30.0</mu1>
    <mu2>30.0</mu2>
    <maxVel>1.0</maxVel>
    <minDepth>0.001</minDepth>
  </gazebo>
  <gazebo reference="right_link1">
    <kp>1000000.0</kp>
    <kd>100.0</kd>
    <mu1>30.0</mu1>
    <mu2>30.0</mu2>
    <maxVel>1.0</maxVel>
    <minDepth>0.001</minDepth>
  </gazebo>
  <gazebo reference="right_link2">
    <kp>1000000.0</kp>
    <kd>100.0</kd>
    <mu1>30.0</mu1>
    <mu2>30.0</mu2>
    <maxVel>1.0</maxVel>
    <minDepth>0.001</minDepth>
  </gazebo>
  <gazebo reference="right_link3">
    <kp>1000000.0</kp>
    <kd>100.0</kd>
    <mu1>30.0</mu1>
    <mu2>30.0</mu2>
    <maxVel>1.0</maxVel>
    <minDepth>0.001</minDepth>
  </gazebo>
  <gazebo reference="right_link4">
    <kp>1000000.0</kp>
    <kd>100.0</kd>
    <mu1>30.0</mu1>
    <mu2>30.0</mu2>
    <maxVel>1.0</maxVel>
    <minDepth>0.001</minDepth>
  </gazebo>
  <gazebo reference="right_link5">
    <kp>1000000.0</kp>
    <kd>100.0</kd>
    <mu1>30.0</mu1>
    <mu2>30.0</mu2>
    <maxVel>1.0</maxVel>
    <minDepth>0.001</minDepth>
  </gazebo>
  <gazebo reference="right_link6">
    <kp>1000000.0</kp>
    <kd>100.0</kd>
    <mu1>30.0</mu1>
    <mu2>30.0</mu2>
    <maxVel>1.0</maxVel>
    <minDepth>0.001</minDepth>
  </gazebo>
  <gazebo reference="right_link_gripper">
    <kp>1000000.0</kp>
    <kd>100.0</kd>
    <mu1>30.0</mu1>
    <mu2>30.0</mu2>
    <maxVel>1.0</maxVel>
    <minDepth>0.001</minDepth>
  </gazebo>
  <gazebo reference="left_link1">
    <kp>1000000.0</kp>
    <kd>100.0</kd>
    <mu1>30.0</mu1>
    <mu2>30.0</mu2>
    <maxVel>1.0</maxVel>
    <minDepth>0.001</minDepth>
  </gazebo>
  <gazebo reference="left_link2">
    <kp>1000000.0</kp>
    <kd>100.0</kd>
    <mu1>30.0</mu1>
    <mu2>30.0</mu2>
    <maxVel>1.0</maxVel>
    <minDepth>0.001</minDepth>
  </gazebo>
  <gazebo reference="left_link3">
    <kp>1000000.0</kp>
    <kd>100.0</kd>
    <mu1>30.0</mu1>
    <mu2>30.0</mu2>
    <maxVel>1.0</maxVel>
    <minDepth>0.001</minDepth>
  </gazebo>
  <gazebo reference="left_link4">
    <kp>1000000.0</kp>
    <kd>100.0</kd>
    <mu1>30.0</mu1>
    <mu2>30.0</mu2>
    <maxVel>1.0</maxVel>
    <minDepth>0.001</minDepth>
  </gazebo>
  <gazebo reference="left_link5">
    <kp>1000000.0</kp>
    <kd>100.0</kd>
    <mu1>30.0</mu1>
    <mu2>30.0</mu2>
    <maxVel>1.0</maxVel>
    <minDepth>0.001</minDepth>
  </gazebo>
  <gazebo reference="left_link6">
    <kp>1000000.0</kp>
    <kd>100.0</kd>
    <mu1>30.0</mu1>
    <mu2>30.0</mu2>
    <maxVel>1.0</maxVel>
    <minDepth>0.001</minDepth>
  </gazebo>
  <gazebo reference="left_link_gripper">
    <kp>1000000.0</kp>
    <kd>100.0</kd>
    <mu1>30.0</mu1>
    <mu2>30.0</mu2>
    <maxVel>1.0</maxVel>
    <minDepth>0.001</minDepth>
  </gazebo>
  <gazebo reference="neck_link1">
    <kp>1000000.0</kp>
    <kd>100.0</kd>
    <mu1>30.0</mu1>
    <mu2>30.0</mu2>
    <maxVel>1.0</maxVel>
    <minDepth>0.001</minDepth>
  </gazebo>
  <gazebo reference="neck_link2">
    <kp>1000000.0</kp>
    <kd>100.0</kd>
    <mu1>30.0</mu1>
    <mu2>30.0</mu2>
    <maxVel>1.0</maxVel>
    <minDepth>0.001</minDepth>
  </gazebo>
  <transmission name="trans1">
    <type>transmission_interface/SimpleTransmission</type>
    <joint name="right_joint1">
      <hardwareInterface>PositionJointInterface</hardwareInterface>
    </joint>
    <actuator name="actuator1">
      <mechanicalReduction>1</mechanicalReduction>
      <hardwareInterface>PositionJointInterface</hardwareInterface>
    </actuator>
  </transmission>
  <transmission name="trans2">
    <type>transmission_interface/SimpleTransmission</type>
    <joint name="right_joint2">
      <hardwareInterface>PositionJointInterface</hardwareInterface>
    </joint>
    <actuator name="actuator2">
      <mechanicalReduction>1</mechanicalReduction>
      <hardwareInterface>PositionJointInterface</hardwareInterface>
    </actuator>
  </transmission>
  <transmission name="trans3">
    <type>transmission_interface/SimpleTransmission</type>
    <joint name="right_joint3">
      <hardwareInterface>PositionJointInterface</hardwareInterface>
    </joint>
    <actuator name="actuator3">
      <mechanicalReduction>1</mechanicalReduction>
      <hardwareInterface>PositionJointInterface</hardwareInterface>
    </actuator>
  </transmission>
  <transmission name="trans4">
    <type>transmission_interface/SimpleTransmission</type>
    <joint name="right_joint4">
      <hardwareInterface>PositionJointInterface</hardwareInterface>
    </joint>
    <actuator name="actuator4">
      <mechanicalReduction>1</mechanicalReduction>
      <hardwareInterface>PositionJointInterface</hardwareInterface>
    </actuator>
  </transmission>
  <transmission name="trans5">
    <type>transmission_interface/SimpleTransmission</type>
    <joint name="right_joint5">
      <hardwareInterface>PositionJointInterface</hardwareInterface>
    </joint>
    <actuator name="actuator5">
      <mechanicalReduction>1</mechanicalReduction>
      <hardwareInterface>PositionJointInterface</hardwareInterface>
    </actuator>
  </transmission>
  <transmission name="trans6">
    <type>transmission_interface/SimpleTransmission</type>
    <joint name="right_joint6">
      <hardwareInterface>PositionJointInterface</hardwareInterface>
    </joint>
    <actuator name="actuator6">
      <mechanicalReduction>1</mechanicalReduction>
      <hardwareInterface>PositionJointInterface</hardwareInterface>
    </actuator>
  </transmission>
  <transmission name="trans7">
    <type>transmission_interface/SimpleTransmission</type>
    <joint name="right_gripper_joint">
      <hardwareInterface>PositionJointInterface</hardwareInterface>
    </joint>
    <actuator name="actuator7">
      <mechanicalReduction>1</mechanicalReduction>
      <hardwareInterface>PositionJointInterface</hardwareInterface>
    </actuator>
  </transmission>
  <transmission name="trans8">
    <type>transmission_interface/SimpleTransmission</type>
    <joint name="left_joint1">
      <hardwareInterface>PositionJointInterface</hardwareInterface>
    </joint>
    <actuator name="actuator8">
      <mechanicalReduction>1</mechanicalReduction>
      <hardwareInterface>PositionJointInterface</hardwareInterface>
    </actuator>
  </transmission>
  <transmission name="trans9">
    <type>transmission_interface/SimpleTransmission</type>
    <joint name="left_joint2">
      <hardwareInterface>PositionJointInterface</hardwareInterface>
    </joint>
    <actuator name="actuator9">
      <mechanicalReduction>1</mechanicalReduction>
      <hardwareInterface>PositionJointInterface</hardwareInterface>
    </actuator>
  </transmission>
  <transmission name="trans10">
    <type>transmission_interface/SimpleTransmission</type>
    <joint name="left_joint3">
      <hardwareInterface>PositionJointInterface</hardwareInterface>
    </joint>
    <actuator name="actuator10">
      <mechanicalReduction>1</mechanicalReduction>
      <hardwareInterface>PositionJointInterface</hardwareInterface>
    </actuator>
  </transmission>
  <transmission name="trans11">
    <type>transmission_interface/SimpleTransmission</type>
    <joint name="left_joint4">
      <hardwareInterface>PositionJointInterface</hardwareInterface>
    </joint>
    <actuator name="actuator11">
      <mechanicalReduction>1</mechanicalReduction>
      <hardwareInterface>PositionJointInterface</hardwareInterface>
    </actuator>
  </transmission>
  <transmission name="trans12">
    <type>transmission_interface/SimpleTransmission</type>
    <joint name="left_joint5">
      <hardwareInterface>PositionJointInterface</hardwareInterface>
    </joint>
    <actuator name="actuator12">
      <mechanicalReduction>1</mechanicalReduction>
      <hardwareInterface>PositionJointInterface</hardwareInterface>
    </actuator>
  </transmission>
  <transmission name="trans13">
    <type>transmission_interface/SimpleTransmission</type>
    <joint name="left_joint6">
      <hardwareInterface>PositionJointInterface</hardwareInterface>
    </joint>
    <actuator name="actuator13">
      <mechanicalReduction>1</mechanicalReduction>
      <hardwareInterface>PositionJointInterface</hardwareInterface>
    </actuator>
  </transmission>
  <transmission name="trans14">
    <type>transmission_interface/SimpleTransmission</type>
    <joint name="left_gripper_joint">
      <hardwareInterface>PositionJointInterface</hardwareInterface>
    </joint>
    <actuator name="actuator14">
      <mechanicalReduction>1</mechanicalReduction>
      <hardwareInterface>PositionJointInterface</hardwareInterface>
    </actuator>
  </transmission>
  <transmission name="trans15">
    <type>transmission_interface/SimpleTransmission</type>
    <joint name="neck_joint1">
      <hardwareInterface>PositionJointInterface</hardwareInterface>
    </joint>
    <actuator name="actuator15">
      <mechanicalReduction>1</mechanicalReduction>
      <hardwareInterface>PositionJointInterface</hardwareInterface>
    </actuator>
  </transmission>
  <transmission name="trans16">
    <type>transmission_interface/SimpleTransmission</type>
    <joint name="neck_joint2">
      <hardwareInterface>PositionJointInterface</hardwareInterface>
    </joint>
    <actuator name="actuator16">
      <mechanicalReduction>1</mechanicalReduction>
      <hardwareInterface>PositionJointInterface</hardwareInterface>
    </actuator>
  </transmission>
  <gazebo reference="right_link_gripper">
    <sensor name="right_gripper_bumper" type="contact">
      <always_on>true</always_on>
      <update_rate>50.0</update_rate>
      <contact>
        <collision>right_link_gripper_collision</collision>
      </contact>
      <plugin filename="libignition-gazebo-contact-system.so" name="ignition::gazebo::systems::Contact">
        </plugin>
    </sensor>
  </gazebo>
  <gazebo reference="left_link_gripper">
    <sensor name="left_gripper_bumper" type="contact">
      <always_on>true</always_on>
      <update_rate>50.0</update_rate>
      <contact>
        <collision>left_link_gripper_collision</collision>
      </contact>
      <plugin filename="libignition-gazebo-contact-system.so" name="ignition::gazebo::systems::Contact">
        </plugin>
    </sensor>
  </gazebo>
  <ros2_control is_async="true" name="FollowerSystem" type="system">
    <hardware>
      <plugin>gz_ros2_control/GazeboSimSystem</plugin>
    </hardware>
    <!-- 오른쪽 팔 -->
    <joint name="right_joint1">
      <command_interface name="position"/>
      <state_interface name="position"/>
      <state_interface name="velocity"/>
      <param name="ID">11</param>
    </joint>
    <joint name="right_joint2">
      <command_interface name="position"/>
      <state_interface name="position"/>
      <state_interface name="velocity"/>
      <param name="ID">12</param>
    </joint>
    <joint name="right_joint3">
      <command_interface name="position"/>
      <state_interface name="position"/>
      <state_interface name="velocity"/>
      <param name="ID">13</param>
    </joint>
    <joint name="right_joint4">
      <command_interface name="position"/>
      <state_interface name="position"/>
      <state_interface name="velocity"/>
      <param name="ID">14</param>
    </joint>
    <joint name="right_joint5">
      <command_interface name="position"/>
      <state_interface name="position"/>
      <state_interface name="velocity"/>
      <param name="ID">15</param>
    </joint>
    <joint name="right_joint6">
      <command_interface name="position"/>
      <state_interface name="position"/>
      <state_interface name="velocity"/>
      <param name="ID">16</param>
    </joint>
    <joint name="right_joint_gripper">
      <command_interface name="position"/>
      <state_interface name="position"/>
      <state_interface name="velocity"/>
      <param name="ID">17</param>
    </joint>
    <!-- 왼쪽 팔 -->
    <joint name="left_joint1">
      <command_interface name="position"/>
      <state_interface name="position"/>
      <state_interface name="velocity"/>
      <param name="ID">21</param>
    </joint>
    <joint name="left_joint2">
      <command_interface name="position"/>
      <state_interface name="position"/>
      <state_interface name="velocity"/>
      <param name="ID">22</param>
    </joint>
    <joint name="left_joint3">
      <command_interface name="position"/>
      <state_interface name="position"/>
      <state_interface name="velocity"/>
      <param name="ID">23</param>
    </joint>
    <joint name="left_joint4">
      <command_interface name="position"/>
      <state_interface name="position"/>
      <state_interface name="velocity"/>
      <param name="ID">24</param>
    </joint>
    <joint name="left_joint5">
      <command_interface name="position"/>
      <state_interface name="position"/>
      <state_interface name="velocity"/>
      <param name="ID">25</param>
    </joint>
    <joint name="left_joint6">
      <command_interface name="position"/>
      <state_interface name="position"/>
      <state_interface name="velocity"/>
      <param name="ID">26</param>
    </joint>
    <joint name="left_joint_gripper">
      <command_interface name="position"/>
      <state_interface name="position"/>
      <state_interface name="velocity"/>
      <param name="ID">27</param>
    </joint>
    <!-- neck joint -->
    <joint name="neck_joint1">
      <command_interface name="position"/>
      <state_interface name="position"/>
      <state_interface name="velocity"/>
      <param name="ID">31</param>
    </joint>
    <joint name="neck_joint2">
      <command_interface name="position"/>
      <state_interface name="position"/>
      <state_interface name="velocity"/>
      <param name="ID">32</param>
    </joint>
  </ros2_control>
  <gazebo>
    <plugin filename="libign_ros2_control-system.so" name="ign_ros2_control::IgnitionROS2ControlPlugin">
      <parameters>/home/shin/avatar_ws/install/avatar_bringup/share/avatar_bringup/config/follower/hardware_controller_manager.yaml</parameters>
    </plugin>
  </gazebo>
</robot>
